Workbook

Sheet Rate Card
A1: FIRE DOOR REMEDIAL WORKS — RATE CARD | Jay Davis / WestPark Interiors
A2: MOCK RATES — FOR DEVELOPMENT/TESTING ONLY. Alex to replace with actual rates. Yellow = input cells.
A3: Updated 19 March 2026: B11 (lipping repair) and B12 (leaf void infill) added. Height band variants on A-series. These cover ART 01 and ART 02 in the EAS/FireDNA system.
A4: CODE | B4: DESCRIPTION | C4: UNIT | D4: MAT'S | E4: LABOUR | F4: T & J | G4: HUMP | H4: TOTAL RATE | I4: NOTES
B5: A — FULL DOOR REPLACEMENT (supply & fit certified fire door set including frame)
A6: A01 | B6: FD30 — Single Leaf, Paint Grade, Height up to 2040mm | C6: no | D6: 320 | E6: 180 | F6: 25 | G6: 30 | H6: 555 | I6: Standard height — most common
A7: A02 | B7: FD30 — Single Leaf, Paint Grade, Height 2040–2400mm | C7: no | D7: 370 | E7: 200 | F7: 25 | G7: 30 | H7: 625 | I7: Height uplift band
A8: A03 | B8: FD30 — Single Leaf, Paint Grade, Height 2400–2730mm | C8: no | D8: 420 | E8: 220 | F8: 25 | G8: 35 | H8: 700 | I8: Tallest standard band
A9: A04 | B9: FD30 — Double Leaf, Paint Grade, Height up to 2040mm | C9: no | D9: 580 | E9: 280 | F9: 40 | G9: 50 | H9: 950 | I9: Double leaf
A10: A05 | B10: FD30S — Single Leaf, Paint Grade + Smoke Seals, Height up to 2040mm | C10: no | D10: 380 | E10: 190 | F10: 25 | G10: 30 | H10: 625 | I10: FD30S = FD30 + seals
A11: A06 | B11: FD30S — Single Leaf, Paint Grade + Smoke Seals, Height 2040–2400mm | C11: no | D11: 430 | E11: 210 | F11: 25 | G11: 30 | H11: 695 | I11: Height uplift
A12: A07 | B12: FD30S — Single Leaf, Paint Grade + Smoke Seals, Height 2400–2730mm | C12: no | D12: 480 | E12: 230 | F12: 25 | G12: 35 | H12: 770 | I12: Tallest band
A13: A08 | B13: FD30S — Double Leaf, Paint Grade + Smoke Seals, Height up to 2040mm | C13: no | D13: 650 | E13: 300 | F13: 40 | G13: 50 | H13: 1040 | I13: Double leaf FD30S
A14: A09 | B14: FD60S — Single Leaf, Paint Grade + Smoke Seals, Height up to 2040mm | C14: no | D14: 480 | E14: 220 | F14: 30 | G14: 35 | H14: 765 | I14: 60-min — required by fire strategy
A15: A10 | B15: FD60S — Single Leaf, Paint Grade + Smoke Seals, Height 2040–2400mm | C15: no | D15: 540 | E15: 240 | F15: 30 | G15: 35 | H15: 845 | I15: Height uplift
A16: A11 | B16: FD60S — Double Leaf, Paint Grade + Smoke Seals, Height up to 2040mm | C16: no | D16: 780 | E16: 340 | F16: 45 | G16: 55 | H16: 1220 | I16: Double leaf FD60S
A17: A12 | B17: E/O Hardwood Veneer Finish — any size (uplift per door) | C17: no | D17: 120 | E17: 0 | F17: 0 | G17: 0 | H17: 120 | I17: On top of base rate
... A20: A15 | B20: E/O Fire-Rated Vision Panel over 300 x 600mm | C20: no | D20: 130 | E20: 55 | F20: 5 | G20: 5 | H20: 195 | I20: Larger vision panel
B21: B — REMEDIAL WORKS (no door replacement — note: does NOT produce a certified fire door set)
A22: B01 | B22: Supply & fit intumescent + smoke seals — head, jambs, meeting edges | C22: no | D22: 45 | E22: 65 | F22: 5 | G22: 5 | H22: 120 | I22: Most common remedial action
A23: B02 | B23: Supply & fit intumescent seals only — no smoke seal | C23: no | D23: 30 | E23: 50 | F23: 5 | G23: 5 | H23: 120 | I23: Lower spec
A24: B03 | B24: Replace overhead door closer — supply & fit, CE-marked BS EN 1154 | C24: no | D24: 85 | E24: 70 | F24: 5 | G24: 10 | H24: 170 | I24: Standard closer replacement
A25: B04 | B25: Replace / fix hinge set — screws or full replacement, BS EN 1935 Grade 11 | C25: no | D25: 35 | E25: 45 | F25: 5 | G25: 5 | H25: 90 | I25: Check whether screws or full hinge needed
A26: B05 | B26: Replace lever handles / latch set — supply & fit, CE-marked ironmongery | C26: no | D26: 40 | E26: 45 | F26: 5 | G26: 5 | H26: 95 | I26: SSS finish unless specified
A27: B06 | B27: Fire-stop frame-to-wall gap — intumescent mastic / ablative batt | C27: no | D27: 25 | E27: 55 | F27: 5 | G27: 5 | H27: 90 | I27: Per door
A28: B07 | B28: Add or replace fire door signage — correct type per door (Keep Shut / Keep Locked) | C28: no | D28: 12 | E28: 25 | F28: 3 | G28: 0 | H28: 40 | I28: Per door — 2 signs per leaf
A29: B08 | B29: Supply & fit electromagnetic hold-open device — fire alarm linked | C29: no | D29: 180 | E29: 120 | F29: 10 | G29: 15 | H29: 325 | I29: Requires electrical connection
A30: B09 | B30: Replace threshold / automatic drop seal | C30: no | D30: 55 | E30: 60 | F30: 5 | G30: 5 | H30: 125 | I30: Per door
A31: B10 | B31: Adjust / re-hang door leaf — binding, distortion, incorrect gaps, snagging on floor | C31: no | D31: 0 | E31: 75 | F31: 5 | G31: 5 | H31: 120 | I31: Labour only
A32: B11 | B32: Door lipping repair — damaged / missing lipping re-lipped with hardwood (min 640kg/m3) *** NEW *** | C32: no | D32: 40 | E32: 85 | F32: 5 | G32: 10 | H32: 140 | I32: Covers ART 01 in EAS/FireDNA system. Common fault — appears on ~20% of doors surveyed.
A33: B12 | B33: Door leaf void infill — repair hole/void from removed hardware using hardwood timber insert *** NEW *** | C33: no | D33: 35 | E33: 75 | F33: 5 | G33: 10 | H33: 125 | I33: Covers ART 02 in EAS/FireDNA system. Appears frequently on tenant doors. Per hole/void.
B34: C — PRELIMINARIES & ANCILLARIES
A35: C01 | B35: Mobilisation / Site setup — fixed call-out per visit | C35: visit | D35: 0 | E35: 120 | F35: 20 | G35: 30 | H35: 170 | I35: Travel, van, tools, PPE
A36: C02 | B36: Waste removal & disposal — per door (average) | C36: no | D36: 15 | E36: 25 | F36: 0 | G36: 10 | H36: 50 | I36: Removed doors, packaging, debris
A37: C03 | B37: Certification & completion documentation — per door | C37: no | D37: 0 | E37: 35 | F37: 5 | G37: 0 | H37: 40 | I37: Photo record, cert, handover pack
A38: C04 | B38: Out-of-hours uplift — per day if required | C38: day | D38: 0 | E38: 200 | F38: 0 | G38: 0 | H38: 200 | I38: Evening / weekend premium
A39: C05 | B39: Scaffold / access equipment — PROVISIONAL | C39: item | D39: 0 | E39: 0 | F39: 0 | G39: 0 | H39: 0 | I39: Where standard access not possible

Sheet Door Schedule
A1: FIRE DOOR REMEDIAL WORKS — DOOR SCHEDULE | AI-populated from survey PDF or Excel
A2: Survey: AlphaSights Thames Court | EAS Interiors Ltd | BM TRADA 1470 | 6 March 2026 | 39 doors across Level 2 & Level 3
A3: DOOR ID | B3: LOCATION | C3: DOOR TYPE | D3: CURRENT RATING | E3: LEAF CONFIG | F3: LEAF SIZE | G3: FINISH | H3: SEALS | I3: CLOSER | J3: VISION PANEL | K3: ACTION DESCRIPTION | L3: SEVERITY | M3: DUE DATE | N3: OPT A REMEDIAL? | O3: OPT B REPLACE? | P3: OPT B BASE ITEM | Q3: QTY | R3: E/O OVERSIZE? | S3: E/O HARDWOOD? | T3: E/O EXTERNAL? | U3: E/O VISION? | V3: NOTES / FLAGS
A4: Floor 1-1 | B4: Floor 1 | C4: From Survey | D4: Unknown | E4: Single Leaf | F4: Unknown | G4: Paint | H4: To Check | I4: To Check | J4: To Check | K4: Hinges missing screws; Missing seal at top of door, where self-closer replaced | L4: MEDIUM | N4: YES | O4: PENDING | P4: B01 | Q4: B01 | R4: NO | S4: NO | T4: NO | U4: NO
A5: Floor 1-4 | B5: Floor 1 | C5: From Survey | D5: Unknown | E5: Single Leaf | F5: Unknown | G5: Paint | H5: To Check | I5: To Check | J5: To Check | K5: Requires adjustment to overcome latch. | L5: MEDIUM | N5: YES | O5: PENDING | P5: B05 | Q5: B05 | R5: NO | S5: NO | T5: NO | U5: NO
A6: Floor 1-5 | B6: Floor 1 | C6: From Survey | D6: Unknown | E6: Single Leaf | F6: Unknown | G6: Paint | H6: To Check | I6: To Check | J6: To Check | K6: Requires adjustment to overcome latch. | L6: MEDIUM | N6: YES | O6: PENDING | P6: B05 | Q6: B05 | R6: NO | S6: NO | T6: NO | U6: NO
A7: Floor 1-7 | B7: Floor 1 | C7: From Survey | D7: Unknown | E7: Single Leaf | F7: Unknown | G7: Paint | H7: To Check | I7: To Check | J7: To Check | K7: Intumescent strip has been painted over | L7: MEDIUM | N7: YES | O7: PENDING | P7: B02 | Q7: B02 | R7: NO | S7: NO | T7: NO | U7: NO
A8: Floor 1-11 | B8: Floor 1 | C8: From Survey | D8: Unknown | E8: Single Leaf | F8: Unknown | G8: Paint | H8: To Check | I8: To Check | J8: To Check | K8: Coming away on the bottom edge; Perco double chains noted in use on door | L8: MEDIUM | N8: YES | O8: PENDING | P8: B01 | Q8: B08, B01 | R8: NO | S8: NO | T8: NO | U8: NO
A9: Floor 1-14 | B9: Floor 1 | C9: From Survey | D9: Unknown | E9: Single Leaf | F9: Unknown | G9: Paint | H9: To Check | I9: To Check | J9: To Check | K9: Not Fitted; None fitted.; Not Fitted | L9: MEDIUM | N9: YES | O9: PENDING | P9: B01 | Q9: B01 | R9: NO | S9: NO | T9: NO | U9: NO
A10: Floor 1-18 | B10: Floor 1 | C10: From Survey | D10: Unknown | E10: Single Leaf | F10: Unknown | G10: Paint | H10: To Check | I10: To Check | J10: To Check | K10: Not Fitted; Intumescent only.; Not Fitted | L10: MEDIUM | N10: YES | O10: PENDING | P10: B01 | Q10: B02, B01 | R10: NO | S10: NO | T10: NO | U10: NO
A11: Floor 1-20 | B11: Floor 1 | C11: From Survey | D11: Unknown | E11: Single Leaf | F11: Unknown | G11: Paint | H11: To Check | I11: To Check | J11: To Check | K11: Unable to open door and check.; Not Fitted; Unable to open door and check.; Unable to open door and check. | L11: MEDIUM | N11: YES | O11: PENDING | P11: B01 | Q11: B01 | R11: NO | S11: NO | T11: NO | U11: NO | V11: ⚠️ Unable to inspect - needs revisit
A12: Floor 1-22 | B12: Floor 1 | C12: From Survey | D12: Unknown | E12: Single Leaf | F12: Unknown | G12: Paint | H12: To Check | I12: To Check | J12: To Check | K12: Not Fitted; Damage to smoke seal | L12: MEDIUM | N12: YES | O12: PENDING | P12: B01 | Q12: B01 | R12: NO | S12: NO | T12: NO | U12: NO
A13: Floor 2-3 | B13: Floor 2 | C13: From Survey | D13: Unknown | E13: Single Leaf | F13: Unknown | G13: Paint | H13: To Check | I13: To Check | J13: To Check | K13: Hinges missing screws; Not Fitted | L13: MEDIUM | N13: YES | O13: PENDING | P13: B01 | Q13: B01 | R13: NO | S13: NO | T13: NO | U13: NO
A14: Floor 2-5 | B14: Floor 2 | C14: From Survey | D14: Unknown | E14: Single Leaf | F14: Unknown | G14: Paint | H14: To Check | I14: To Check | J14: To Check | K14: Unable to open door fully and check.; Unable to open fully door and check.; Unable to open fully door and check. | L14: LOW | N14: YES | O14: PENDING | P14: B01 | Q14: MANUAL REVIEW | R14: NO | S14: NO | T14: NO | U14: NO | V14: ⚠️ Unable to inspect - needs revisit
A15: Floor 3-1 | B15: Floor 3 | C15: From Survey | D15: Unknown | E15: Single Leaf | F15: Unknown | G15: Paint | H15: To Check | I15: To Check | J15: To Check | K15: Not Fitted; Intumescent only.; Unable to open door to check | L15: MEDIUM | N15: YES | O15: PENDING | P15: B01 | Q15: B02, B01 | R15: NO | S15: NO | T15: NO | U15: NO | V15: ⚠️ Unable to inspect - needs revisit
A16: Floor 3-3 | B16: Floor 3 | C16: From Survey | D16: Unknown | E16: Single Leaf | F16: Unknown | G16: Paint | H16: To Check | I16: To Check | J16: To Check | K16: Not Fitted; Smoke seal worn on top edge | L16: MEDIUM | N16: YES | O16: PENDING | P16: B01 | Q16: B01 | R16: NO | S16: NO | T16: NO | U16: NO
A17: Floor 3-6 | B17: Floor 3 | C17: From Survey | D17: Unknown | E17: Single Leaf | F17: Unknown | G17: Paint | H17: To Check | I17: To Check | J17: To Check | K17: Not closing as catching on floor. | L17: MEDIUM | N17: YES | O17: PENDING | P17: B10 | Q17: B10 | R17: NO | S17: NO | T17: NO | U17: NO
A18: Floor 3-11 | B18: Floor 3 | C18: From Survey | D18: Unknown | E18: Single Leaf | F18: Unknown | G18: Paint | H18: To Check | I18: To Check | J18: To Check | K18: Unable to open door to check.; Not Fitted; Unable to open door to check.; Unable to open door to check | L18: MEDIUM | N18: YES | O18: PENDING | P18: B01 | Q18: B01 | R18: NO | S18: NO | T18: NO | U18: NO | V18: ⚠️ Unable to inspect - needs revisit

Sheet Quote Sheet
A1: FIRE DOOR REMEDIAL WORKS — QUOTE SHEET
A2: Quote Ref: | B2: WP-2026-001 | Q2: TARGET MARGIN: | R2: 0.35
A3: Date: | B3: 06/03/2026
A4: Client: | B4: Natixis CITYSPACE - RETEST
A5: Site:
A6: Building:
A8: ITEM | B8: DESCRIPTION | C8: QTY | D8: UNIT | E8: RATE | F8: TOTAL | G8: MAT'S | H8: MAT'S TOTAL | I8: LAB | J8: LAB TOTAL | K8: T & J | L8: T & J TOTAL | M8: HUMP | N8: HUMP TOTAL | O8: TOTAL COST | P8: PROFIT | Q8: % MARGIN | R8: % PROFIT
A9: OPT A | B9: OPTION A — Remedial Works Only | Does NOT produce a certified fire door set
B10: Quantities = doors marked YES in Door Schedule Option A column. Type 2 (Excel) surveys populate this section.
A11: A.01 | B11: Supply & fit intumescent + smoke seals | C11: =COUNTIFS('Door Schedule'!$P:$P,"B01",'Door Schedule'!$N:$N,"YES") | D11: no | E11: =IFERROR(VLOOKUP("B01",'Rate Card'!$A:$H,8,FALSE()),0) | F11: =IF(C11=0,0,C11*E11) | G11: =IFERROR(VLOOKUP("B01",'Rate Card'!$A:$H,4,FALSE()),0) | H11: =IF(C11=0,0,C11*G11) | I11: =IFERROR(VLOOKUP("B01",'Rate Card'!$A:$H,5,FALSE()),0) | J11: =IF(C11=0,0,C11*I11) | K11: =IFERROR(VLOOKUP("B01",'Rate Card'!$A:$H,6,FALSE()),0) | L11: =IF(C11=0,0,C11*K11) | M11: =IFERROR(VLOOKUP("B01",'Rate Card'!$A:$H,7,FALSE()),0) | N11: =IF(C11=0,0,C11*M11) | O11: =SUM(H11,J11,L11,N11) | P11: =F11-O11 | Q11: =IF(F11=0,0,P11/F11) | R11: =IF(O11=0,0,P11/O11)
A12: A.02 | B12: Supply & fit intumescent seals only | C12: =COUNTIFS('Door Schedule'!$P:$P,"B02",'Door Schedule'!$N:$N,"YES") | D12: no | E12: =IFERROR(VLOOKUP("B02",'Rate Card'!$A:$H,8,FALSE()),0) | F12: =IF(C12=0,0,C12*E12) | G12: =IFERROR(VLOOKUP("B02",'Rate Card'!$A:$H,4,FALSE()),0) | H12: =IF(C12=0,0,C12*G12) | I12: =IFERROR(VLOOKUP("B02",'Rate Card'!$A:$H,5,FALSE()),0) | J12: =IF(C12=0,0,C12*I12) | K12: =IFERROR(VLOOKUP("B02",'Rate Card'!$A:$H,6,FALSE()),0) | L12: =IF(C12=0,0,C12*K12) | M12: =IFERROR(VLOOKUP("B02",'Rate Card'!$A:$H,7,FALSE()),0) | N12: =IF(C12=0,0,C12*M12) | O12: =SUM(H12,J12,L12,N12) | P12: =F12-O12 | Q12: =IF(F12=0,0,P12/F12) | R12: =IF(O12=0,0,P12/O12)
A13: A.03 | B13: Replace overhead door closer — supply & fit | C13: =COUNTIFS('Door Schedule'!$P:$P,"B03",'Door Schedule'!$N:$N,"YES") | D13: no | E13: =IFERROR(VLOOKUP("B03",'Rate Card'!$A:$H,8,FALSE()),0) | F13: =IF(C13=0,0,C13*E13) | G13: =IFERROR(VLOOKUP("B03",'Rate Card'!$A:$H,4,FALSE()),0) | H13: =IF(C13=0,0,C13*G13) | I13: =IFERROR(VLOOKUP("B03",'Rate Card'!$A:$H,5,FALSE()),0) | J13: =IF(C13=0,0,C13*I13) | K13: =IFERROR(VLOOKUP("B03",'Rate Card'!$A:$H,6,FALSE()),0) | L13: =IF(C13=0,0,C13*K13) | M13: =IFERROR(VLOOKUP("B03",'Rate Card'!$A:$H,7,FALSE()),0) | N13: =IF(C13=0,0,C13*M13) | O13: =SUM(H13,J13,L13,N13) | P13: =F13-O13 | Q13: =IF(F13=0,0,P13/F13) | R13: =IF(O13=0,0,P13/O13)
A14: A.04 | B14: Replace / fix hinge set | C14: =COUNTIFS('Door Schedule'!$P:$P,"B04",'Door Schedule'!$N:$N,"YES") | D14: no | E14: =IFERROR(VLOOKUP("B04",'Rate Card'!$A:$H,8,FALSE()),0) | F14: =IF(C14=0,0,C14*E14) | G14: =IFERROR(VLOOKUP("B04",'Rate Card'!$A:$H,4,FALSE()),0) | H14: =IF(C14=0,0,C14*G14) | I14: =IFERROR(VLOOKUP("B04",'Rate Card'!$A:$H,5,FALSE()),0) | J14: =IF(C14=0,0,C14*I14) | K14: =IFERROR(VLOOKUP("B04",'Rate Card'!$A:$H,6,FALSE()),0) | L14: =IF(C14=0,0,C14*K14) | M14: =IFERROR(VLOOKUP("B04",'Rate Card'!$A:$H,7,FALSE()),0) | N14: =IF(C14=0,0,C14*M14) | O14: =SUM(H14,J14,L14,N14) | P14: =F14-O14 | Q14: =IF(F14=0,0,P14/F14) | R14: =IF(O14=0,0,P14/O14)
A15: A.05 | B15: Replace lever handles / latch set | C15: =COUNTIFS('Door Schedule'!$P:$P,"B05",'Door Schedule'!$N:$N,"YES") | D15: no | E15: =IFERROR(VLOOKUP("B05",'Rate Card'!$A:$H,8,FALSE()),0) | F15: =IF(C15=0,0,C15*E15) | G15: =IFERROR(VLOOKUP("B05",'Rate Card'!$A:$H,4,FALSE()),0) | H15: =IF(C15=0,0,C15*G15) | I15: =IFERROR(VLOOKUP("B05",'Rate Card'!$A:$H,5,FALSE()),0) | J15: =IF(C15=0,0,C15*I15) | K15: =IFERROR(VLOOKUP("B05",'Rate Card'!$A:$H,6,FALSE()),0) | L15: =IF(C15=0,0,C15*K15) | M15: =IFERROR(VLOOKUP("B05",'Rate Card'!$A:$H,7,FALSE()),0) | N15: =IF(C15=0,0,C15*M15) | O15: =SUM(H15,J15,L15,N15) | P15: =F15-O15 | Q15: =IF(F15=0,0,P15/F15) | R15: =IF(O15=0,0,P15/O15)
A16: A.06 | B16: Fire-stop frame-to-wall gap | C16: =COUNTIFS('Door Schedule'!$P:$P,"B06",'Door Schedule'!$N:$N,"YES") | D16: no | E16: =IFERROR(VLOOKUP("B06",'Rate Card'!$A:$H,8,FALSE()),0) | F16: =IF(C16=0,0,C16*E16) | G16: =IFERROR(VLOOKUP("B06",'Rate Card'!$A:$H,4,FALSE()),0) | H16: =IF(C16=0,0,C16*G16) | I16: =IFERROR(VLOOKUP("B06",'Rate Card'!$A:$H,5,FALSE()),0) | J16: =IF(C16=0,0,C16*I16) | K16: =IFERROR(VLOOKUP("B06",'Rate Card'!$A:$H,6,FALSE()),0) | L16: =IF(C16=0,0,C16*K16) | M16: =IFERROR(VLOOKUP("B06",'Rate Card'!$A:$H,7,FALSE()),0) | N16: =IF(C16=0,0,C16*M16) | O16: =SUM(H16,J16,L16,N16) | P16: =F16-O16 | Q16: =IF(F16=0,0,P16/F16) | R16: =IF(O16=0,0,P16/O16)
A17: A.07 | B17: Add / replace fire door signage | C17: =COUNTIFS('Door Schedule'!$P:$P,"B07",'Door Schedule'!$N:$N,"YES") | D17: no | E17: =IFERROR(VLOOKUP("B07",'Rate Card'!$A:$H,8,FALSE()),0) | F17: =IF(C17=0,0,C17*E17) | G17: =IFERROR(VLOOKUP("B07",'Rate Card'!$A:$H,4,FALSE()),0) | H17: =IF(C17=0,0,C17*G17) | I17: =IFERROR(VLOOKUP("B07",'Rate Card'!$A:$H,5,FALSE()),0) | J17: =IF(C17=0,0,C17*I17) | K17: =IFERROR(VLOOKUP("B07",'Rate Card'!$A:$H,6,FALSE()),0) | L17: =IF(C17=0,0,C17*K17) | M17: =IFERROR(VLOOKUP("B07",'Rate Card'!$A:$H,7,FALSE()),0) | N17: =IF(C17=0,0,C17*M17) | O17: =SUM(H17,J17,L17,N17) | P17: =F17-O17 | Q17: =IF(F17=0,0,P17/F17) | R17: =IF(O17=0,0,P17/O17)
A18: A.08 | B18: Supply & fit electromagnetic hold-open device | C18: =COUNTIFS('Door Schedule'!$P:$P,"B08",'Door Schedule'!$N:$N,"YES") | D18: no | E18: =IFERROR(VLOOKUP("B08",'Rate Card'!$A:$H,8,FALSE()),0) | F18: =IF(C18=0,0,C18*E18) | G18: =IFERROR(VLOOKUP("B08",'Rate Card'!$A:$H,4,FALSE()),0) | H18: =IF(C18=0,0,C18*G18) | I18: =IFERROR(VLOOKUP("B08",'Rate Card'!$A:$H,5,FALSE()),0) | J18: =IF(C18=0,0,C18*I18) | K18: =IFERROR(VLOOKUP("B08",'Rate Card'!$A:$H,6,FALSE()),0) | L18: =IF(C18=0,0,C18*K18) | M18: =IFERROR(VLOOKUP("B08",'Rate Card'!$A:$H,7,FALSE()),0) | N18: =IF(C18=0,0,C18*M18) | O18: =SUM(H18,J18,L18,N18) | P18: =F18-O18 | Q18: =IF(F18=0,0,P18/F18) | R18: =IF(O18=0,0,P18/O18)
A19: A.09 | B19: Replace threshold / drop seal | C19: =COUNTIFS('Door Schedule'!$P:$P,"B09",'Door Schedule'!$N:$N,"YES") | D19: no | E19: =IFERROR(VLOOKUP("B09",'Rate Card'!$A:$H,8,FALSE()),0) | F19: =IF(C19=0,0,C19*E19) | G19: =IFERROR(VLOOKUP("B09",'Rate Card'!$A:$H,4,FALSE()),0) | H19: =IF(C19=0,0,C19*G19) | I19: =IFERROR(VLOOKUP("B09",'Rate Card'!$A:$H,5,FALSE()),0) | J19: =IF(C19=0,0,C19*I19) | K19: =IFERROR(VLOOKUP("B09",'Rate Card'!$A:$H,6,FALSE()),0) | L19: =IF(C19=0,0,C19*K19) | M19: =IFERROR(VLOOKUP("B09",'Rate Card'!$A:$H,7,FALSE()),0) | N19: =IF(C19=0,0,C19*M19) | O19: =SUM(H19,J19,L19,N19) | P19: =F19-O19 | Q19: =IF(F19=0,0,P19/F19) | R19: =IF(O19=0,0,P19/O19)
A20: A.10 | B20: Adjust / re-hang door leaf | C20: =COUNTIFS('Door Schedule'!$P:$P,"B10",'Door Schedule'!$N:$N,"YES") | D20: no | E20: =IFERROR(VLOOKUP("B10",'Rate Card'!$A:$H,8,FALSE()),0) | F20: =IF(C20=0,0,C20*E20) | G20: =IFERROR(VLOOKUP("B10",'Rate Card'!$A:$H,4,FALSE()),0) | H20: =IF(C20=0,0,C20*G20) | I20: =IFERROR(VLOOKUP("B10",'Rate Card'!$A:$H,5,FALSE()),0) | J20: =IF(C20=0,0,C20*I20) | K20: =IFERROR(VLOOKUP("B10",'Rate Card'!$A:$H,6,FALSE()),0) | L20: =IF(C20=0,0,C20*K20) | M20: =IFERROR(VLOOKUP("B10",'Rate Card'!$A:$H,7,FALSE()),0) | N20: =IF(C20=0,0,C20*M20) | O20: =SUM(H20,J20,L20,N20) | P20: =F20-O20 | Q20: =IF(F20=0,0,P20/F20) | R20: =IF(O20=0,0,P20/O20)
A21: A.11 | B21: Door lipping repair (hardwood re-lip) *** B11 | C21: =COUNTIFS('Door Schedule'!$P:$P,"B11",'Door Schedule'!$N:$N,"YES") | D21: no | E21: =IFERROR(VLOOKUP("B11",'Rate Card'!$A:$H,8,FALSE()),0) | F21: =IF(C21=0,0,C21*E21) | G21: =IFERROR(VLOOKUP("B11",'Rate Card'!$A:$H,4,FALSE()),0) | H21: =IF(C21=0,0,C21*G21) | I21: =IFERROR(VLOOKUP("B11",'Rate Card'!$A:$H,5,FALSE()),0) | J21: =IF(C21=0,0,C21*I21) | K21: =IFERROR(VLOOKUP("B11",'Rate Card'!$A:$H,6,FALSE()),0) | L21: =IF(C21=0,0,C21*K21) | M21: =IFERROR(VLOOKUP("B11",'Rate Card'!$A:$H,7,FALSE()),0) | N21: =IF(C21=0,0,C21*M21) | O21: =SUM(H21,J21,L21,N21) | P21: =F21-O21 | Q21: =IF(F21=0,0,P21/F21) | R21: =IF(O21=0,0,P21/O21)
A22: A.12 | B22: Door leaf void infill (hardwood timber insert) *** B12 | C22: =COUNTIFS('Door Schedule'!$P:$P,"B12",'Door Schedule'!$N:$N,"YES") | D22: no | E22: =IFERROR(VLOOKUP("B12",'Rate Card'!$A:$H,8,FALSE()),0) | F22: =IF(C22=0,0,C22*E22) | G22: =IFERROR(VLOOKUP("B12",'Rate Card'!$A:$H,4,FALSE()),0) | H22: =IF(C22=0,0,C22*G22) | I22: =IFERROR(VLOOKUP("B12",'Rate Card'!$A:$H,5,FALSE()),0) | J22: =IF(C22=0,0,C22*I22) | K22: =IFERROR(VLOOKUP("B12",'Rate Card'!$A:$H,6,FALSE()),0) | L22: =IF(C22=0,0,C22*K22) | M22: =IFERROR(VLOOKUP("B12",'Rate Card'!$A:$H,7,FALSE()),0) | N22: =IF(C22=0,0,C22*M22) | O22: =SUM(H22,J22,L22,N22) | P22: =F22-O22 | Q22: =IF(F22=0,0,P22/F22) | R22: =IF(O22=0,0,P22/O22)
A24: OPT B | B24: OPTION B — Full Door Replacement | Certified fire door sets — RECOMMENDED
B25: Quantities = doors marked YES in Door Schedule Option B column, by BASE ITEM code. Type 2 surveys show PENDING — fire strategy required.
A26: B.01 | B26: FD30 — Single Leaf, Paint Grade, Height up to 2040mm | C26: =COUNTIFS('Door Schedule'!$P:$P,"A01",'Door Schedule'!$O:$O,"YES") | D26: no | E26: =IFERROR(VLOOKUP("A01",'Rate Card'!$A:$H,8,FALSE()),0) | F26: =IF(C26=0,0,C26*E26) | G26: =IFERROR(VLOOKUP("A01",'Rate Card'!$A:$H,4,FALSE()),0) | H26: =IF(C26=0,0,C26*G26) | I26: =IFERROR(VLOOKUP("A01",'Rate Card'!$A:$H,5,FALSE()),0) | J26: =IF(C26=0,0,C26*I26) | K26: =IFERROR(VLOOKUP("A01",'Rate Card'!$A:$H,6,FALSE()),0) | L26: =IF(C26=0,0,C26*K26) | M26: =IFERROR(VLOOKUP("A01",'Rate Card'!$A:$H,7,FALSE()),0) | N26: =IF(C26=0,0,C26*M26) | O26: =SUM(H26,J26,L26,N26) | P26: =F26-O26 | Q26: =IF(F26=0,0,P26/F26) | R26: =IF(O26=0,0,P26/O26)
A27: B.02 | B27: FD30 — Single Leaf, Paint Grade, Height 2040–2400mm | C27: =COUNTIFS('Door Schedule'!$P:$P,"A02",'Door Schedule'!$O:$O,"YES") | D27: no | E27: =IFERROR(VLOOKUP("A02",'Rate Card'!$A:$H,8,FALSE()),0) | F27: =IF(C27=0,0,C27*E27) | G27: =IFERROR(VLOOKUP("A02",'Rate Card'!$A:$H,4,FALSE()),0) | H27: =IF(C27=0,0,C27*G27) | I27: =IFERROR(VLOOKUP("A02",'Rate Card'!$A:$H,5,FALSE()),0) | J27: =IF(C27=0,0,C27*I27) | K27: =IFERROR(VLOOKUP("A02",'Rate Card'!$A:$H,6,FALSE()),0) | L27: =IF(C27=0,0,C27*K27) | M27: =IFERROR(VLOOKUP("A02",'Rate Card'!$A:$H,7,FALSE()),0) | N27: =IF(C27=0,0,C27*M27) | O27: =SUM(H27,J27,L27,N27) | P27: =F27-O27 | Q27: =IF(F27=0,0,P27/F27) | R27: =IF(O27=0,0,P27/O27)
A28: B.03 | B28: FD30 — Single Leaf, Paint Grade, Height 2400–2730mm | C28: =COUNTIFS('Door Schedule'!$P:$P,"A03",'Door Schedule'!$O:$O,"YES") | D28: no | E28: =IFERROR(VLOOKUP("A03",'Rate Card'!$A:$H,8,FALSE()),0) | F28: =IF(C28=0,0,C28*E28) | G28: =IFERROR(VLOOKUP("A03",'Rate Card'!$A:$H,4,FALSE()),0) | H28: =IF(C28=0,0,C28*G28) | I28: =IFERROR(VLOOKUP("A03",'Rate Card'!$A:$H,5,FALSE()),0) | J28: =IF(C28=0,0,C28*I28) | K28: =IFERROR(VLOOKUP("A03",'Rate Card'!$A:$H,6,FALSE()),0) | L28: =IF(C28=0,0,C28*K28) | M28: =IFERROR(VLOOKUP("A03",'Rate Card'!$A:$H,7,FALSE()),0) | N28: =IF(C28=0,0,C28*M28) | O28: =SUM(H28,J28,L28,N28) | P28: =F28-O28 | Q28: =IF(F28=0,0,P28/F28) | R28: =IF(O28=0,0,P28/O28)
A29: B.04 | B29: FD30 — Double Leaf, Paint Grade, Height up to 2040mm | C29: =COUNTIFS('Door Schedule'!$P:$P,"A04",'Door Schedule'!$O:$O,"YES") | D29: no | E29: =IFERROR(VLOOKUP("A04",'Rate Card'!$A:$H,8,FALSE()),0) | F29: =IF(C29=0,0,C29*E29) | G29: =IFERROR(VLOOKUP("A04",'Rate Card'!$A:$H,4,FALSE()),0) | H29: =IF(C29=0,0,C29*G29) | I29: =IFERROR(VLOOKUP("A04",'Rate Card'!$A:$H,5,FALSE()),0) | J29: =IF(C29=0,0,C29*I29) | K29: =IFERROR(VLOOKUP("A04",'Rate Card'!$A:$H,6,FALSE()),0) | L29: =IF(C29=0,0,C29*K29) | M29: =IFERROR(VLOOKUP("A04",'Rate Card'!$A:$H,7,FALSE()),0) | N29: =IF(C29=0,0,C29*M29) | O29: =SUM(H29,J29,L29,N29) | P29: =F29-O29 | Q29: =IF(F29=0,0,P29/F29) | R29: =IF(O29=0,0,P29/O29)
A30: B.05 | B30: FD30S — Single Leaf, Paint Grade + Smoke Seals, Height up to 2040mm | C30: =COUNTIFS('Door Schedule'!$P:$P,"A05",'Door Schedule'!$O:$O,"YES") | D30: no | E30: =IFERROR(VLOOKUP("A05",'Rate Card'!$A:$H,8,FALSE()),0) | F30: =IF(C30=0,0,C30*E30) | G30: =IFERROR(VLOOKUP("A05",'Rate Card'!$A:$H,4,FALSE()),0) | H30: =IF(C30=0,0,C30*G30) | I30: =IFERROR(VLOOKUP("A05",'Rate Card'!$A:$H,5,FALSE()),0) | J30: =IF(C30=0,0,C30*I30) | K30: =IFERROR(VLOOKUP("A05",'Rate Card'!$A:$H,6,FALSE()),0) | L30: =IF(C30=0,0,C30*K30) | M30: =IFERROR(VLOOKUP("A05",'Rate Card'!$A:$H,7,FALSE()),0) | N30: =IF(C30=0,0,C30*M30) | O30: =SUM(H30,J30,L30,N30) | P30: =F30-O30 | Q30: =IF(F30=0,0,P30/F30) | R30: =IF(O30=0,0,P30/O30)
A31: B.06 | B31: FD30S — Single Leaf, Paint Grade + Smoke Seals, Height 2040–2400mm | C31: =COUNTIFS('Door Schedule'!$P:$P,"A06",'Door Schedule'!$O:$O,"YES") | D31: no | E31: =IFERROR(VLOOKUP("A06",'Rate Card'!$A:$H,8,FALSE()),0) | F31: =IF(C31=0,0,C31*E31) | G31: =IFERROR(VLOOKUP("A06",'Rate Card'!$A:$H,4,FALSE()),0) | H31: =IF(C31=0,0,C31*G31) | I31: =IFERROR(VLOOKUP("A06",'Rate Card'!$A:$H,5,FALSE()),0) | J31: =IF(C31=0,0,C31*I31) | K31: =IFERROR(VLOOKUP("A06",'Rate Card'!$A:$H,6,FALSE()),0) | L31: =IF(C31=0,0,C31*K31) | M31: =IFERROR(VLOOKUP("A06",'Rate Card'!$A:$H,7,FALSE()),0) | N31: =IF(C31=0,0,C31*M31) | O31: =SUM(H31,J31,L31,N31) | P31: =F31-O31 | Q31: =IF(F31=0,0,P31/F31) | R31: =IF(O31=0,0,P31/O31)
A32: B.07 | B32: FD30S — Single Leaf, Paint Grade + Smoke Seals, Height 2400–2730mm | C32: =COUNTIFS('Door Schedule'!$P:$P,"A07",'Door Schedule'!$O:$O,"YES") | D32: no | E32: =IFERROR(VLOOKUP("A07",'Rate Card'!$A:$H,8,FALSE()),0) | F32: =IF(C32=0,0,C32*E32) | G32: =IFERROR(VLOOKUP("A07",'Rate Card'!$A:$H,4,FALSE()),0) | H32: =IF(C32=0,0,C32*G32) | I32: =IFERROR(VLOOKUP("A07",'Rate Card'!$A:$H,5,FALSE()),0) | J32: =IF(C32=0,0,C32*I32) | K32: =IFERROR(VLOOKUP("A07",'Rate Card'!$A:$H,6,FALSE()),0) | L32: =IF(C32=0,0,C32*K32) | M32: =IFERROR(VLOOKUP("A07",'Rate Card'!$A:$H,7,FALSE()),0) | N32: =IF(C32=0,0,C32*M32) | O32: =SUM(H32,J32,L32,N32) | P32: =F32-O32 | Q32: =IF(F32=0,0,P32/F32) | R32: =IF(O32=0,0,P32/O32)
A33: B.08 | B33: FD30S — Double Leaf, Paint Grade + Smoke Seals, Height up to 2040mm | C33: =COUNTIFS('Door Schedule'!$P:$P,"A08",'Door Schedule'!$O:$O,"YES") | D33: no | E33: =IFERROR(VLOOKUP("A08",'Rate Card'!$A:$H,8,FALSE()),0) | F33: =IF(C33=0,0,C33*E33) | G33: =IFERROR(VLOOKUP("A08",'Rate Card'!$A:$H,4,FALSE()),0) | H33: =IF(C33=0,0,C33*G33) | I33: =IFERROR(VLOOKUP("A08",'Rate Card'!$A:$H,5,FALSE()),0) | J33: =IF(C33=0,0,C33*I33) | K33: =IFERROR(VLOOKUP("A08",'Rate Card'!$A:$H,6,FALSE()),0) | L33: =IF(C33=0,0,C33*K33) | M33: =IFERROR(VLOOKUP("A08",'Rate Card'!$A:$H,7,FALSE()),0) | N33: =IF(C33=0,0,C33*M33) | O33: =SUM(H33,J33,L33,N33) | P33: =F33-O33 | Q33: =IF(F33=0,0,P33/F33) | R33: =IF(O33=0,0,P33/O33)
A34: B.09 | B34: FD60S — Single Leaf, Paint Grade + Smoke Seals, Height up to 2040mm | C34: =COUNTIFS('Door Schedule'!$P:$P,"A09",'Door Schedule'!$O:$O,"YES") | D34: no | E34: =IFERROR(VLOOKUP("A09",'Rate Card'!$A:$H,8,FALSE()),0) | F34: =IF(C34=0,0,C34*E34) | G34: =IFERROR(VLOOKUP("A09",'Rate Card'!$A:$H,4,FALSE()),0) | H34: =IF(C34=0,0,C34*G34) | I34: =IFERROR(VLOOKUP("A09",'Rate Card'!$A:$H,5,FALSE()),0) | J34: =IF(C34=0,0,C34*I34) | K34: =IFERROR(VLOOKUP("A09",'Rate Card'!$A:$H,6,FALSE()),0) | L34: =IF(C34=0,0,C34*K34) | M34: =IFERROR(VLOOKUP("A09",'Rate Card'!$A:$H,7,FALSE()),0) | N34: =IF(C34=0,0,C34*M34) | O34: =SUM(H34,J34,L34,N34) | P34: =F34-O34 | Q34: =IF(F34=0,0,P34/F34) | R34: =IF(O34=0,0,P34/O34)
A35: B.10 | B35: FD60S — Single Leaf, Paint Grade + Smoke Seals, Height 2040–2400mm | C35: =COUNTIFS('Door Schedule'!$P:$P,"A10",'Door Schedule'!$O:$O,"YES") | D35: no | E35: =IFERROR(VLOOKUP("A10",'Rate Card'!$A:$H,8,FALSE()),0) | F35: =IF(C35=0,0,C35*E35) | G35: =IFERROR(VLOOKUP("A10",'Rate Card'!$A:$H,4,FALSE()),0) | H35: =IF(C35=0,0,C35*G35) | I35: =IFERROR(VLOOKUP("A10",'Rate Card'!$A:$H,5,FALSE()),0) | J35: =IF(C35=0,0,C35*I35) | K35: =IFERROR(VLOOKUP("A10",'Rate Card'!$A:$H,6,FALSE()),0) | L35: =IF(C35=0,0,C35*K35) | M35: =IFERROR(VLOOKUP("A10",'Rate Card'!$A:$H,7,FALSE()),0) | N35: =IF(C35=0,0,C35*M35) | O35: =SUM(H35,J35,L35,N35) | P35: =F35-O35 | Q35: =IF(F35=0,0,P35/F35) | R35: =IF(O35=0,0,P35/O35)
A36: B.11 | B36: FD60S — Double Leaf, Paint Grade + Smoke Seals, Height up to 2040mm | C36: =COUNTIFS('Door Schedule'!$P:$P,"A11",'Door Schedule'!$O:$O,"YES") | D36: no | E36: =IFERROR(VLOOKUP("A11",'Rate Card'!$A:$H,8,FALSE()),0) | F36: =IF(C36=0,0,C36*E36) | G36: =IFERROR(VLOOKUP("A11",'Rate Card'!$A:$H,4,FALSE()),0) | H36: =IF(C36=0,0,C36*G36) | I36: =IFERROR(VLOOKUP("A11",'Rate Card'!$A:$H,5,FALSE()),0) | J36: =IF(C36=0,0,C36*I36) | K36: =IFERROR(VLOOKUP("A11",'Rate Card'!$A:$H,6,FALSE()),0) | L36: =IF(C36=0,0,C36*K36) | M36: =IFERROR(VLOOKUP("A11",'Rate Card'!$A:$H,7,FALSE()),0) | N36: =IF(C36=0,0,C36*M36) | O36: =SUM(H36,J36,L36,N36) | P36: =F36-O36 | Q36: =IF(F36=0,0,P36/F36) | R36: =IF(O36=0,0,P36/O36)
A37: B.12 | B37: E/O Hardwood Veneer Finish (per door) | C37: =COUNTIFS('Door Schedule'!$P:$P,"A12",'Door Schedule'!$O:$O,"YES") | D37: no | E37: =IFERROR(VLOOKUP("A12",'Rate Card'!$A:$H,8,FALSE()),0) | F37: =IF(C37=0,0,C37*E37) | G37: =IFERROR(VLOOKUP("A12",'Rate Card'!$A:$H,4,FALSE()),0) | H37: =IF(C37=0,0,C37*G37) | I37: =IFERROR(VLOOKUP("A12",'Rate Card'!$A:$H,5,FALSE()),0) | J37: =IF(C37=0,0,C37*I37) | K37: =IFERROR(VLOOKUP("A12",'Rate Card'!$A:$H,6,FALSE()),0) | L37: =IF(C37=0,0,C37*K37) | M37: =IFERROR(VLOOKUP("A12",'Rate Card'!$A:$H,7,FALSE()),0) | N37: =IF(C37=0,0,C37*M37) | O37: =SUM(H37,J37,L37,N37) | P37: =F37-O37 | Q37: =IF(F37=0,0,P37/F37) | R37: =IF(O37=0,0,P37/O37)
A38: B.13 | B38: E/O External Grade Specification (per door) | C38: =COUNTIFS('Door Schedule'!$P:$P,"A13",'Door Schedule'!$O:$O,"YES") | D38: no | E38: =IFERROR(VLOOKUP("A13",'Rate Card'!$A:$H,8,FALSE()),0) | F38: =IF(C38=0,0,C38*E38) | G38: =IFERROR(VLOOKUP("A13",'Rate Card'!$A:$H,4,FALSE()),0) | H38: =IF(C38=0,0,C38*G38) | I38: =IFERROR(VLOOKUP("A13",'Rate Card'!$A:$H,5,FALSE()),0) | J38: =IF(C38=0,0,C38*I38) | K38: =IFERROR(VLOOKUP("A13",'Rate Card'!$A:$H,6,FALSE()),0) | L38: =IF(C38=0,0,C38*K38) | M38: =IFERROR(VLOOKUP("A13",'Rate Card'!$A:$H,7,FALSE()),0) | N38: =IF(C38=0,0,C38*M38) | O38: =SUM(H38,J38,L38,N38) | P38: =F38-O38 | Q38: =IF(F38=0,0,P38/F38) | R38: =IF(O38=0,0,P38/O38)
A39: B.14 | B39: E/O Fire-Rated Vision Panel up to 300 x 600mm | C39: =COUNTIFS('Door Schedule'!$P:$P,"A14",'Door Schedule'!$O:$O,"YES") | D39: no | E39: =IFERROR(VLOOKUP("A14",'Rate Card'!$A:$H,8,FALSE()),0) | F39: =IF(C39=0,0,C39*E39) | G39: =IFERROR(VLOOKUP("A14",'Rate Card'!$A:$H,4,FALSE()),0) | H39: =IF(C39=0,0,C39*G39) | I39: =IFERROR(VLOOKUP("A14",'Rate Card'!$A:$H,5,FALSE()),0) | J39: =IF(C39=0,0,C39*I39) | K39: =IFERROR(VLOOKUP("A14",'Rate Card'!$A:$H,6,FALSE()),0) | L39: =IF(C39=0,0,C39*K39) | M39: =IFERROR(VLOOKUP("A14",'Rate Card'!$A:$H,7,FALSE()),0) | N39: =IF(C39=0,0,C39*M39) | O39: =SUM(H39,J39,L39,N39) | P39: =F39-O39 | Q39: =IF(F39=0,0,P39/F39) | R39: =IF(O39=0,0,P39/O39)
A40: B.15 | B40: E/O Fire-Rated Vision Panel over 300 x 600mm | C40: =COUNTIFS('Door Schedule'!$P:$P,"A15",'Door Schedule'!$O:$O,"YES") | D40: no | E40: =IFERROR(VLOOKUP("A15",'Rate Card'!$A:$H,8,FALSE()),0) | F40: =IF(C40=0,0,C40*E40) | G40: =IFERROR(VLOOKUP("A15",'Rate Card'!$A:$H,4,FALSE()),0) | H40: =IF(C40=0,0,C40*G40) | I40: =IFERROR(VLOOKUP("A15",'Rate Card'!$A:$H,5,FALSE()),0) | J40: =IF(C40=0,0,C40*I40) | K40: =IFERROR(VLOOKUP("A15",'Rate Card'!$A:$H,6,FALSE()),0) | L40: =IF(C40=0,0,C40*K40) | M40: =IFERROR(VLOOKUP("A15",'Rate Card'!$A:$H,7,FALSE()),0) | N40: =IF(C40=0,0,C40*M40) | O40: =SUM(H40,J40,L40,N40) | P40: =F40-O40 | Q40: =IF(F40=0,0,P40/F40) | R40: =IF(O40=0,0,P40/O40)
A42: PRE | B42: PRELIMINARIES & ANCILLARIES | Applied to whichever option is chosen
A43: P.01 | B43: Mobilisation / Site setup (per visit) | C43: 1 | D43: visit | E43: =IFERROR(VLOOKUP("C01",'Rate Card'!$A:$H,8,FALSE()),0) | F43: =IF(C43=0,0,C43*E43) | G43: =IFERROR(VLOOKUP("C01",'Rate Card'!$A:$H,4,FALSE()),0) | H43: =IF(C43=0,0,C43*G43) | I43: =IFERROR(VLOOKUP("C01",'Rate Card'!$A:$H,5,FALSE()),0) | J43: =IF(C43=0,0,C43*I43) | K43: =IFERROR(VLOOKUP("C01",'Rate Card'!$A:$H,6,FALSE()),0) | L43: =IF(C43=0,0,C43*K43) | M43: =IFERROR(VLOOKUP("C01",'Rate Card'!$A:$H,7,FALSE()),0) | N43: =IF(C43=0,0,C43*M43) | O43: =SUM(H43,J43,L43,N43) | P43: =F43-O43 | Q43: =IF(F43=0,0,P43/F43) | R43: =IF(O43=0,0,P43/O43)
...

Sheet Material Call-Off
A1: FIRE DOOR REMEDIAL WORKS — MATERIAL CALL-OFF | Auto-generated on job win
A2: IMPORTANT: Door sizes (leaf width and height) must be physically measured on site before ordering. All other components can be ordered from this list immediately.
A3: B11 (lipping) and B12 (void infill) added to components list. Quantities for these are counted from Door Schedule — typical rate approx 20% of surveyed doors.
A7: DOOR ID | B7: LOCATION | C7: COMPONENT | D7: QTY | E7: UNIT | F7: ORDER STATUS | G7: SUPPLIER | H7: COST EX VAT | I7: NOTES / FLAGS
B8: FIRE DOORS — SIZES MUST BE MEASURED ON SITE BEFORE ORDERING (Option B only)
A9: A12-L3 | B9: Core 5 tenant door to WCs | C9: FD60S Single Leaf — MEASURE BEFORE ORDER | D9: 1 | E9: no | F9: Pending | I9: Survey dims: 2650x950x70mm — VERIFY ON SITE
A10: A14-L3 | B10: Core 4 tenant DB riser | C10: FD30 Double Leaf — MEASURE BEFORE ORDER | D10: 1 | E10: no | F10: Pending | I10: Survey dims: 2650x1810x135mm — VERIFY ON SITE
B12: COMPONENTS — READY TO ORDER (quantities aggregated across all doors)
A13: ALL | B13: All doors | C13: Overhead door closer — CE-marked, BS EN 1154 | D13: =COUNTIF('Door Schedule'!I:I,"Overhead Closer") | E13: no | F13: Ready to order | I13: Count from Door Schedule col I
A14: ALL | B14: All doors | C14: Hinge set (3 hinges) — BS EN 1935 Grade 11 | D14: =COUNTA('Door Schedule'!A:A)-4 | E14: sets | F14: Ready to order | I14: One set per door requiring hinge work
A15: ALL | B15: All doors | C15: Intumescent + smoke seals — 10mm x 4mm double fin white | D15: =COUNTIF('Door Schedule'!H:H,"*Smoke*") | E15: doors | F15: Ready to order | I15: One linear kit per door
A16: ALL | B16: All doors | C16: Intumescent seals only (no smoke seal) | D16: =COUNTIF('Door Schedule'!N:N,"YES")-COUNTIF('Door Schedule'!H:H,"*Smoke*") | E16: doors | F16: Ready to order | I16: Doors with seals action but no smoke seal
A17: ALL | B17: All doors | C17: Fire door signage — 'Keep Shut' / 'Keep Locked' | D17: =COUNTIF('Door Schedule'!N:N,"YES")*2 | E17: no | F17: Ready to order | I17: 2 signs per door (both sides)
A18: ALL | B18: All doors | C18: Drop seal / automatic threshold seal | D18: 0 | E18: no | F18: Check survey | I18: Count from doors with B09 code
A19: ALL | B19: All doors | C19: Lever handle / latch set — CE-marked, SSS finish | D19: 0 | E19: no | F19: Check survey | I19: Count from doors with B05 code
A20: ALL | B20: All doors | C20: Intumescent mastic — fire-stopping frame gaps | D20: 0 | E20: items | F20: Check survey | I20: Count from doors with B06 code
A21: ALL | B21: All doors | C21: Hardwood lipping material (B11) — min density 640kg/m3 | D21: =COUNTIF('Door Schedule'!P:P,"B11") | E21: doors | F21: Ready to order | I21: NEW: count from B11-coded doors
A22: ALL | B22: All doors | C22: Hardwood timber inserts for void infill (B12) | D22: =COUNTIF('Door Schedule'!P:P,"B12") | E22: doors | F22: Ready to order | I22: NEW: count from B12-coded doors. Per void/hole.

Sheet Client Summary
A1: FIRE DOOR REMEDIAL WORKS — CLIENT PROPOSAL SUMMARY
A3: Client: | B3: ='Quote Sheet'!B4
A4: Site: | B4: ='Quote Sheet'!B5
A5: Building: | B5: ='Quote Sheet'!B6
A6: Date: | B6: ='Quote Sheet'!B3
A7: Quote Ref: | B7: ='Quote Sheet'!B2
A9: SECTION | B9: DESCRIPTION | C9: NET COST | D9: OPTION A TOTAL | E9: OPTION B TOTAL
A10: A | B10: Remedial Works (seals, closers, hinges, fire-stopping, signage, lipping, void infill) | C10: =SUM(O11,O12,O13,O14,O15,O16,O17,O18,O19,O20,O21,O22,O43,O44,O45,O46,O47) | D10: =SUM(F11,F12,F13,F14,F15,F16,F17,F18,F19,F20,F21,F22,F43,F44,F45,F46,F47) | E10: N/A — Option B only
A11: B | B11: Full Door Replacements (certified fire door sets — RECOMMENDED) | C11: =SUM(O26,O27,O28,O29,O30,O31,O32,O33,O34,O35,O36,O37,O38,O39,O40,O43,O44,O45,O46,O47) | D11: N/A — Option A only | E11: =SUM(F26,F27,F28,F29,F30,F31,F32,F33,F34,F35,F36,F37,F38,F39,F40,F43,F44,F45,F46,F47)
A12: PRE | B12: Preliminaries & Ancillaries | C12: =SUM(O43,O44,O45,O46,O47) | D12: =SUM(F43,F44,F45,F46,F47) | E12: =SUM(F43,F44,F45,F46,F47)
B13: TOTAL INVESTMENT | D13: =SUM(D10:D12) | E13: =SUM(E10:E12)
A15: COMPLIANCE NOTE Option A — Remedial Works Only: These works do not produce a certified fire door set. Fire resistance relies on landlord declaration only. Cheaper but limited assurance. Option B — Full Replacement (RECOMMENDED): Certified fire door sets installed per fire strategy. Full BS-certified compliance, demonstrable liability protection. This is what the assessor recommends. Note: Where input survey is Type 2 (Excel) format, Option B total may show 0 — fire strategy drawings are required to confirm the intended fire rating per door set before replacement can be priced.
B17: Achieved Margins: | D17: ='Quote Sheet'!Q49 | E17: ='Quote Sheet'!Q50
